<?xml version="1.0" ?>
<!-- =================================================================================== -->
<!-- |    This document was autogenerated by xacro from mpo_700.urdf.xacro             | -->
<!-- |    EDITING THIS FILE BY HAND IS NOT RECOMMENDED                                 | -->
<!-- =================================================================================== -->
<robot name="mpo_700">
  <!-- SENSORS -->
  <!-- Sick S300 - Comment/Uncomment if required -->
  <!-- Microscan - Comment/Uncomment if required -->

  <link name="base_link"/>
  <joint name="base_footprint_joint" type="fixed">
    <origin rpy="0 0 0" xyz="0 0 0"/>
    <axis xyz="0 0 -1"/>
    <!-- <limit effort="1000.0" lower="-1e+16" upper="1e+16" velocity="3.5"/> -->
    <joint_properties damping="1" friction="1"/>
    <parent link="base_link"/>
    <child link="base_footprint"/>
  </joint>
  <link name="base_footprint">
    <inertial>
      <mass value="140"/>
      <origin xyz="0 0 0"/>
      <inertia ixx="7.8" ixy="0.0" ixz="0" iyy="7.8" iyz="0.0" izz="7.8"/>
    </inertial>
    <visual>
      <origin rpy="0 0 -1.571" xyz="0.0 0.0 0.0"/>
      <geometry>
        <mesh filename="package://neo_mpo_700-2/robot_model/mpo_700/meshes/MPO-700-BODY.dae" scale="0.001 0.001 0.001"/>
      </geometry>
    </visual>
    <collision>
      <origin rpy="0 0 -1.571" xyz="0. 0. 0."/>
      <geometry>
        <mesh filename="package://neo_mpo_700-2/robot_model/mpo_700/meshes/MPO-700-BODY.dae" scale="0.001 0.001 0.001"/>
      </geometry>
    </collision>
  </link>
  <joint name="mpo_700_caster_front_left_joint" type="revolute">
    <origin rpy="0 0 3.14" xyz="0.24 0.18 0.22"/>
    <axis xyz="0 0 1"/>
    <limit effort="1000.0" lower="-1e+16" upper="1e+16" velocity="6.5"/>
    <joint_properties damping="30" friction="110"/>
    <parent link="base_footprint"/>
    <child link="mpo_700_caster_front_left_link"/>
  </joint>
  <link name="mpo_700_caster_front_left_link">
    <inertial>
      <mass value="12.7"/>
      <origin rpy="0 0 0" xyz="0 0 0"/>
      <inertia ixx="0.27258101" ixy="0" ixz="0" iyy="0.27258101" iyz="0" izz="0.27258101"/>
    </inertial>
    <visual>
      <origin rpy="0 0 0" xyz="0 0 0.0"/>
      <geometry>
        <mesh filename="package://neo_mpo_700-2/robot_model/mpo_700/meshes/MPO-700-HEAD.dae" scale="0.001 0.001 0.001"/>
      </geometry>
    </visual>
    <collision>
      <origin rpy="0 0 0" xyz="0 0 0.0"/>
      <geometry>
        <mesh filename="package://neo_mpo_700-2/robot_model/mpo_700/meshes/MPO-700-HEAD.dae" scale="0.001 0.001 0.001"/>
      </geometry>
    </collision>
  </link>
  <joint name="mpo_700_caster_front_right_joint" type="revolute">
    <origin rpy="0 0 0" xyz="0.24 -0.18 0.22"/>
    <axis xyz="0 0 1"/>
    <limit effort="1000.0" lower="-1e+16" upper="1e+16" velocity="6.5"/>
    <joint_properties damping="30" friction="110"/>
    <parent link="base_footprint"/>
    <child link="mpo_700_caster_front_right_link"/>
  </joint>
  <link name="mpo_700_caster_front_right_link">
    <inertial>
      <mass value="12.7"/>
      <origin rpy="0 0 0" xyz="0 0 0"/>
      <inertia ixx="0.27258101" ixy="0" ixz="0" iyy="0.27258101" iyz="0" izz="0.27258101"/>
    </inertial>
    <visual>
      <origin rpy="0 0 3.14" xyz="0 0 0.0"/>
      <geometry>
        <mesh filename="package://neo_mpo_700-2/robot_model/mpo_700/meshes/MPO-700-HEAD.dae" scale="0.001 0.001 0.001"/>
      </geometry>
    </visual>
    <collision>
      <origin rpy="0 0 3.14" xyz="0 0 0.0"/>
      <geometry>
        <mesh filename="package://neo_mpo_700-2/robot_model/mpo_700/meshes/MPO-700-HEAD.dae" scale="0.001 0.001 0.001"/>
      </geometry>
    </collision>
  </link>
  <joint name="mpo_700_caster_back_left_joint" type="revolute">
    <origin rpy="0 0 3.14" xyz="-0.24 0.18 0.22"/>
    <axis xyz="0 0 1"/>
    <limit effort="1000.0" lower="-1e+16" upper="1e+16" velocity="6.5"/>
    <joint_properties damping="30" friction="110"/>
    <parent link="base_footprint"/>
    <child link="mpo_700_caster_back_left_link"/>
  </joint>
  <link name="mpo_700_caster_back_left_link">
    <inertial>
      <mass value="12.7"/>
      <origin rpy="0 0 0" xyz="0 0 0"/>
      <inertia ixx="0.27258101" ixy="0" ixz="0" iyy="0.27258101" iyz="0" izz="0.27258101"/>
    </inertial>
    <visual>
      <origin rpy="0 0 0" xyz="0 0 0.0"/>
      <geometry>
        <mesh filename="package://neo_mpo_700-2/robot_model/mpo_700/meshes/MPO-700-HEAD.dae" scale="0.001 0.001 0.001"/>
      </geometry>
    </visual>
    <collision>
      <origin rpy="0 0 0" xyz="0 0 0.0"/>
      <geometry>
        <mesh filename="package://neo_mpo_700-2/robot_model/mpo_700/meshes/MPO-700-HEAD.dae" scale="0.001 0.001 0.001"/>
      </geometry>
    </collision>
  </link>
  <joint name="mpo_700_caster_back_right_joint" type="revolute">
    <origin rpy="0 0 0" xyz="-0.24 -0.18 0.22"/>
    <axis xyz="0 0 1"/>
    <limit effort="1000.0" lower="-1e+16" upper="1e+16" velocity="6.5"/>
    <joint_properties damping="30" friction="110"/>
    <parent link="base_footprint"/>
    <child link="mpo_700_caster_back_right_link"/>
  </joint>
  <link name="mpo_700_caster_back_right_link">
    <inertial>
      <mass value="12.7"/>
      <origin rpy="0 0 0" xyz="0 0 0"/>
      <inertia ixx="0.27258101" ixy="0" ixz="0" iyy="0.27258101" iyz="0" izz="0.27258101"/>
    </inertial>
    <visual>
      <origin rpy="0 0 3.14" xyz="0 0 0.0"/>
      <geometry>
        <mesh filename="package://neo_mpo_700-2/robot_model/mpo_700/meshes/MPO-700-HEAD.dae" scale="0.001 0.001 0.001"/>
      </geometry>
    </visual>
    <collision>
      <origin rpy="0 0 3.14" xyz="0 0 0.0"/>
      <geometry>
        <mesh filename="package://neo_mpo_700-2/robot_model/mpo_700/meshes/MPO-700-HEAD.dae" scale="0.001 0.001 0.001"/>
      </geometry>
    </collision>
  </link>
  <joint name="mpo_700_wheel_front_left_joint" type="revolute">
    <origin rpy="0 0 0" xyz="0.0 0.045 -0.12"/>
    <limit effort="1000.0" lower="-1e+16" upper="1e+16" velocity="20.5"/>
    <axis xyz="0 -1 0"/>
    <joint_properties damping="30" friction="110"/>
    <parent link="mpo_700_caster_front_left_link"/>
    <child link="mpo_700_wheel_front_left_link"/>
  </joint>
  <link name="mpo_700_wheel_front_left_link" type="wheel">
    <inertial>
      <mass value="1.2"/>
      <origin rpy="0 0 0" xyz="0 0 0"/>
      <inertia ixx="0.11042056" ixy="0.0" ixz="0.0" iyy="0.11042056" iyz="0.0" izz="0.11042056"/>
    </inertial>
    <visual>
      <origin rpy="0 0 3.14" xyz="0 0 0"/>
      <geometry>
        <mesh filename="package://neo_mpo_700-2/robot_model/mpo_700/meshes/MPO-700-WHEEL.dae" scale="0.001 0.001 0.001"/>
      </geometry>
    </visual>
    <collision>
      <origin rpy="0 0 0" xyz="0 0 0"/>
      <geometry>
        <sphere radius="0.09"/>
        <!-- <mesh filename="package://neo_mpo_700-2/robot_model/mpo_700/meshes/MPO-700-WHEEL.dae" scale="0.001 0.001 0.001"/> -->
      </geometry>
    </collision>
  </link>
  <joint name="mpo_700_wheel_front_right_joint" type="revolute">
    <origin rpy="0 0 3.14" xyz="0.0 -0.045 -0.12"/>
    <limit effort="1000.0" lower="-1e+16" upper="1e+16" velocity="20.5"/>
    <axis xyz="0 -1 0"/>
    <joint_properties damping="30" friction="110"/>
    <parent link="mpo_700_caster_front_right_link"/>
    <child link="mpo_700_wheel_front_right_link"/>
  </joint>
  <link name="mpo_700_wheel_front_right_link" type="wheel">
    <inertial>
      <mass value="1.2"/>
      <origin rpy="0 0 0" xyz="0 0 0"/>
      <inertia ixx="0.11042056" ixy="0.0" ixz="0.0" iyy="0.11042056" iyz="0.0" izz="0.11042056"/>
    </inertial>
    <visual>
      <origin rpy="0 0 3.14" xyz="0 0 0"/>
      <geometry>
        <mesh filename="package://neo_mpo_700-2/robot_model/mpo_700/meshes/MPO-700-WHEEL.dae" scale="0.001 0.001 0.001"/>
      </geometry>
    </visual>
    <collision>
      <origin rpy="0 0 0" xyz="0 0 0"/>
      <geometry>
        <sphere radius="0.09"/>
        <!-- <mesh filename="package://neo_mpo_700-2/robot_model/mpo_700/meshes/MPO-700-WHEEL.dae" scale="0.001 0.001 0.001"/> -->
      </geometry>
    </collision>
  </link>
  <joint name="mpo_700_wheel_back_left_joint" type="revolute">
    <origin rpy="0 0 0" xyz="0.0 0.045 -0.12"/>
    <limit effort="1000.0" lower="-1e+16" upper="1e+16" velocity="20.5"/>
    <axis xyz="0 -1 0"/>
    <joint_properties damping="30" friction="110"/>
    <parent link="mpo_700_caster_back_left_link"/>
    <child link="mpo_700_wheel_back_left_link"/>
  </joint>
  <link name="mpo_700_wheel_back_left_link" type="wheel">
    <inertial>
      <mass value="1.2"/>
      <origin rpy="0 0 0" xyz="0 0 0"/>
      <inertia ixx="0.11042056" ixy="0.0" ixz="0.0" iyy="0.11042056" iyz="0.0" izz="0.11042056"/>
    </inertial>
    <visual>
      <origin rpy="0 0 3.14" xyz="0 0 0"/>
      <geometry>
        <mesh filename="package://neo_mpo_700-2/robot_model/mpo_700/meshes/MPO-700-WHEEL.dae" scale="0.001 0.001 0.001"/>
      </geometry>
    </visual>
    <collision>
      <origin rpy="0 0 0" xyz="0 0 0"/>
      <geometry>
        <sphere radius="0.09"/>
        <!-- <mesh filename="package://neo_mpo_700-2/robot_model/mpo_700/meshes/MPO-700-WHEEL.dae" scale="0.001 0.001 0.001"/> -->
      </geometry>
    </collision>
  </link>
  <joint name="mpo_700_wheel_back_right_joint" type="revolute">
    <origin rpy="0 0 3.14" xyz="0.0 -0.045 -0.12"/>
    <limit effort="1000.0" lower="-1e+16" upper="1e+16" velocity="20.5"/>
    <axis xyz="0 -1 0"/>
    <joint_properties damping="30" friction="110"/>
    <parent link="mpo_700_caster_back_right_link"/>
    <child link="mpo_700_wheel_back_right_link"/>
  </joint>
  <link name="mpo_700_wheel_back_right_link" type="wheel">
    <inertial>
      <mass value="1.2"/>
      <origin rpy="0 0 0" xyz="0 0 0"/>
      <inertia ixx="0.11042056" ixy="0.0" ixz="0.0" iyy="0.11042056" iyz="0.0" izz="0.11042056"/>
    </inertial>
    <visual>
      <origin rpy="0 0 3.14" xyz="0 0 0"/>
      <geometry>
        <mesh filename="package://neo_mpo_700-2/robot_model/mpo_700/meshes/MPO-700-WHEEL.dae" scale="0.001 0.001 0.001"/>
      </geometry>
    </visual>
    <collision>
      <origin rpy="0 0 0" xyz="0 0 0"/>
      <geometry>
        <sphere radius="0.09"/>
        <!-- <mesh filename="package://neo_mpo_700-2/robot_model/mpo_700/meshes/MPO-700-WHEEL.dae" scale="0.001 0.001 0.001"/> -->
      </geometry>
    </collision>
  </link>
  <!-- Sensors -->
  <joint name="lidar_1_joint" type="fixed">
    <axis xyz="0 1 0"/>
    <origin rpy="3.14 0 0.79" xyz="0.338 0.288 0.223"/>
    <parent link="base_link"/>
    <child link="lidar_1_link"/>
  </joint>
  <link name="lidar_1_link" type="laser">
    <inertial>
      <mass value="0.001"/>
      <origin rpy="0 0 0" xyz="0 0 0"/>
      <inertia ixx="0.0001" ixy="0" ixz="0" iyy="0.000001" iyz="0" izz="0.0001"/>
    </inertial>
    <visual>
      <origin rpy="-1.57 0 3.14" xyz="0 0 -0.12"/>
      <geometry>
        <mesh filename="package://neo_mpo_700-2/robot_model/mpo_700/meshes/SICK-S300.dae" scale="0.001 0.001 0.001"/>
      </geometry>
    </visual>
    <collision>
      <origin rpy="-1.57 0 3.14" xyz="0 0 -0.12"/>
      <geometry>
        <mesh filename="package://neo_mpo_700-2/robot_model/mpo_700/meshes/SICK-S300.dae" scale="0.001 0.001 0.001"/>
      </geometry>
    </collision>
  </link>
  <joint name="lidar_2_joint" type="fixed">
    <axis xyz="0 1 0"/>
    <origin rpy="3.14 0 3.93" xyz="-0.338 -0.288 0.223"/>
    <parent link="base_link"/>
    <child link="lidar_2_link"/>
  </joint>
  <link name="lidar_2_link" type="laser">
    <inertial>
      <mass value="0.001"/>
      <origin rpy="0 0 0" xyz="0 0 0"/>
      <inertia ixx="0.0001" ixy="0" ixz="0" iyy="0.000001" iyz="0" izz="0.0001"/>
    </inertial>
    <visual>
      <origin rpy="-1.57 0 3.14" xyz="0 0 -0.12"/>
      <geometry>
        <mesh filename="package://neo_mpo_700-2/robot_model/mpo_700/meshes/SICK-S300.dae" scale="0.001 0.001 0.001"/>
      </geometry>
    </visual>
    <collision>
      <origin rpy="-1.57 0 3.14" xyz="0 0 -0.12"/>
      <geometry>
        <mesh filename="package://neo_mpo_700-2/robot_model/mpo_700/meshes/SICK-S300.dae" scale="0.001 0.001 0.001"/>
      </geometry>
    </collision>
  </link>

  <!-- Arm and it's componenets -->
  <link name="linear_axis_fixed_link">
    <visual>
      <origin rpy="0 0 0" xyz="0 0 0"/>
      <geometry>
        <mesh filename="package://neo_mpo_700-2/robot_model/mpo_700/meshes/linear_axis_base.dae" scale="0.1 0.1 0.1"/>
      </geometry>
    </visual>
    <collision>
      <origin rpy="0 0 0" xyz="0 0 0"/>
      <geometry>
        <mesh filename="package://neo_mpo_700-2/robot_model/mpo_700/meshes/linear_axis_base.dae" scale="0.1 0.1 0.1"/>
      </geometry>
    </collision>
  </link>

  <joint name="linear_axis_fixed_joint" type="fixed">
    <axis xyz="0 1 0"/>
    <origin xyz="0.0 0 0.35" rpy="0 0 1.57" />
    <parent link="base_link"/>
    <child link="linear_axis_fixed_link"/>
  </joint>

  <link name="linear_axis_slide_link">
    <visual>
      <origin rpy="0 0 0" xyz="0 0 0"/>
      <geometry>
        <mesh filename="package://neo_mpo_700-2/robot_model/mpo_700/meshes/linear_axis.dae" scale="0.1 0.1 0.1"/>
      </geometry>
    </visual>
    <collision>
      <origin rpy="0 0 0" xyz="0 0 0"/>
      <geometry>
        <mesh filename="package://neo_mpo_700-2/robot_model/mpo_700/meshes/linear_axis.dae" scale="0.1 0.1 0.1"/>
      </geometry>
    </collision>
  </link>

  <joint name="linear_axis_slide_joint" type="prismatic">
    <axis xyz="0 0 1"/>
    <origin xyz="0.0 -0.314 0.0" rpy="0 0 -1.57" />
    <limit lower="0.1" upper="0.7" effort="54.0" velocity="0.2"/>
    <parent link="linear_axis_fixed_link"/>
    <child link="linear_axis_slide_link"/>
  </joint>

  <ros2_control name="linear_axis_control" type="system">
    <hardware>
      <plugin>nla/NlaHardwareInterface</plugin>
    </hardware>
    <joint name="linear_axis_slide_joint">
      <command_interface name="velocity">
        <!-- Not used in the code as of now -->
        <param name="min">0.01</param>
        <param name="max">0.2</param>
      </command_interface>
      <state_interface name="position"/>
      <param name="initial_position">0.1</param>
    </joint>
    <gpio name="linear_axis_gpio">
      <state_interface name="dig_in_1"/>
      <state_interface name="dig_in_2"/>
    </gpio>
  </ros2_control>
  <!-- uncomment if necessary -->
  <!-- <link name="imu_link">
      <inertial>
        <mass value="0.001" />
        <origin xyz="0 0 0" rpy="0 0 0" />
        <inertia ixx="0.0001" ixy="0" ixz="0" iyy="0.000001" iyz="0" izz="0.0001" />
      </inertial>  
  </link>
  <joint name="imu2_joint" type="fixed">
    <axis xyz="0 1 0"/>
    <origin rpy="0 0 0" xyz="-0.052 0.208 0.266"/>
    <parent link="base_link"/>
    <child link="imu_link"/>
  </joint> -->
</robot>

